2019-11-07 14:12:18,452 ERROR externalParameter.ExternalParameterSelection(ExternalParameterSelection.py:125 onEnableChanged) VI_ERROR_TMO (-1073807339): Timeout expired before operation completed. while enabling instrument asdf
Traceback (most recent call last):
  File "C:\Users\ions\Desktop\IonControl\externalParameter\ExternalParameterSelection.py", line 123, in onEnableChanged
    self.enableInstrument(parameter)
  File "C:\Users\ions\Desktop\IonControl\externalParameter\ExternalParameterSelection.py", line 153, in enableInstrument
    instance = self.classdict[parameter.className](parameter.name, parameter.settings, self.globalDict, parameter.instrument)
  File "C:\Users\ions\Desktop\IonControl\externalParameter\StandardExternalParameter.py", line 315, in __init__
    self.initializeChannelsToExternals()
  File "C:\Users\ions\Desktop\IonControl\externalParameter\ExternalParameterBase.py", line 58, in initializeChannelsToExternals
    self.outputChannels[cname].settings.value = self.getValue(cname)
  File "C:\Users\ions\Desktop\IonControl\externalParameter\StandardExternalParameter.py", line 328, in getValue
    answer = self.synthesizer.query(":FREQ:CW?")
  File "C:\ProgramData\Miniconda3\envs\IonControl\lib\site-packages\pyvisa\resources\messagebased.py", line 569, in query
    return self.read()
  File "C:\ProgramData\Miniconda3\envs\IonControl\lib\site-packages\pyvisa\resources\messagebased.py", line 413, in read
    message = self._read_raw().decode(enco)
  File "C:\ProgramData\Miniconda3\envs\IonControl\lib\site-packages\pyvisa\resources\messagebased.py", line 386, in _read_raw
    chunk, status = self.visalib.read(self.session, size)
  File "C:\ProgramData\Miniconda3\envs\IonControl\lib\site-packages\pyvisa\ctwrapper\functions.py", line 1584, in read
    ret = library.viRead(session, buffer, count, byref(return_count))
  File "C:\ProgramData\Miniconda3\envs\IonControl\lib\site-packages\pyvisa\ctwrapper\highlevel.py", line 188, in _return_handler
    raise errors.VisaIOError(ret_value)
pyvisa.errors.VisaIOError: VI_ERROR_TMO (-1073807339): Timeout expired before operation completed.
2019-11-07 14:15:14,669 ERROR persist.ValueHistory(ValueHistory.py:146 add) (psycopg2.IntegrityError) null value in column "value" violates not-null constraint
DETAIL:  Failing row contains (4, null, null, null, null, 2019-11-07 14:14:29.612018-05).
 [SQL: 'INSERT INTO history_value (source_id, value, bottom, top, unit, upd_date) VALUES (%(source_id)s, %(value)s, %(bottom)s, %(top)s, %(unit)s, %(upd_date)s)'] [parameters: {'source_id': 4, 'value': None, 'bottom': None, 'top': None, 'unit': None, 'upd_date': datetime.datetime(2019, 11, 7, 14, 14, 29, 612018)}] (Background on this error at: http://sqlalche.me/e/gkpj)
2019-11-07 14:15:19,423 ERROR persist.ValueHistory(ValueHistory.py:146 add) (psycopg2.IntegrityError) null value in column "value" violates not-null constraint
DETAIL:  Failing row contains (5, null, null, null, null, 2019-11-07 14:14:29.612018-05).
 [SQL: 'INSERT INTO history_value (source_id, value, bottom, top, unit, upd_date) VALUES (%(source_id)s, %(value)s, %(bottom)s, %(top)s, %(unit)s, %(upd_date)s)'] [parameters: {'source_id': 5, 'value': None, 'bottom': None, 'top': None, 'unit': None, 'upd_date': datetime.datetime(2019, 11, 7, 14, 14, 29, 612018)}] (Background on this error at: http://sqlalche.me/e/gkpj)
2019-11-07 14:15:23,620 ERROR persist.ValueHistory(ValueHistory.py:146 add) (psycopg2.IntegrityError) null value in column "value" violates not-null constraint
DETAIL:  Failing row contains (6, null, null, null, null, 2019-11-07 14:14:29.612018-05).
 [SQL: 'INSERT INTO history_value (source_id, value, bottom, top, unit, upd_date) VALUES (%(source_id)s, %(value)s, %(bottom)s, %(top)s, %(unit)s, %(upd_date)s)'] [parameters: {'source_id': 6, 'value': None, 'bottom': None, 'top': None, 'unit': None, 'upd_date': datetime.datetime(2019, 11, 7, 14, 14, 29, 612018)}] (Background on this error at: http://sqlalche.me/e/gkpj)
2019-11-07 14:15:27,039 ERROR persist.ValueHistory(ValueHistory.py:146 add) (psycopg2.IntegrityError) null value in column "value" violates not-null constraint
DETAIL:  Failing row contains (7, null, null, null, null, 2019-11-07 14:14:29.612018-05).
 [SQL: 'INSERT INTO history_value (source_id, value, bottom, top, unit, upd_date) VALUES (%(source_id)s, %(value)s, %(bottom)s, %(top)s, %(unit)s, %(upd_date)s)'] [parameters: {'source_id': 7, 'value': None, 'bottom': None, 'top': None, 'unit': None, 'upd_date': datetime.datetime(2019, 11, 7, 14, 14, 29, 612018)}] (Background on this error at: http://sqlalche.me/e/gkpj)
2019-11-07 14:15:29,622 ERROR persist.ValueHistory(ValueHistory.py:146 add) (psycopg2.IntegrityError) null value in column "value" violates not-null constraint
DETAIL:  Failing row contains (8, null, null, null, null, 2019-11-07 14:14:29.612018-05).
 [SQL: 'INSERT INTO history_value (source_id, value, bottom, top, unit, upd_date) VALUES (%(source_id)s, %(value)s, %(bottom)s, %(top)s, %(unit)s, %(upd_date)s)'] [parameters: {'source_id': 8, 'value': None, 'bottom': None, 'top': None, 'unit': None, 'upd_date': datetime.datetime(2019, 11, 7, 14, 14, 29, 612018)}] (Background on this error at: http://sqlalche.me/e/gkpj)
